try {
    // ReferenceError
    myFunction();
} catch (err) {
    console.log(err);
}

console.log('Continue with the program...')